Workbook

Sheet Flujo de Caja
A1: 180DC PUCP — Plan de Sostenibilidad Financiera
A2: Flujo de Caja Semanal — Semestre Académico 2026-II
A3: S1 = Semana del 17/08/2026 (inicio del semestre) | S20 = Semana del 28/12/2026 (cierre del semestre) | Moneda: Soles (S/)
A5: Categoría | B5: Concepto | C5: S1 | D5: S2 | E5: S3 | F5: S4 | G5: S5 | H5: S6 | I5: S7 | J5: S8 | K5: S9 | L5: S10 | M5: S11 | N5: S12 | O5: S13 | P5: S14 | Q5: S15 | R5: S16 | S5: S17 | T5: S18 | U5: S19 | V5: S20 | W5: Total Semestre
A6: Semana del | C6: 17/08 | D6: 24/08 | E6: 31/08 | F6: 07/09 | G6: 14/09 | H6: 21/09 | I6: 28/09 | J6: 05/10 | K6: 12/10 | L6: 19/10 | M6: 26/10 | N6: 02/11 | O6: 09/11 | P6: 16/11 | Q6: 23/11 | R6: 30/11 | S6: 07/12 | T6: 14/12 | U6: 21/12 | V6: 28/12
A7: SALDO INICIAL | C7: 92.87 | D7: =C45 -> -251.25 | E7: =D45 -> -229.25 | F7: =E45 -> -224.25 | G7: =F45 -> -224.25 | H7: =G45 -> -224.25 | I7: =H45 -> -224.25 | J7: =I45 -> -224.25 | K7: =J45 -> -224.25 | ... V7: =U45 -> -224.25
A8: (+) INGRESOS
A9: Membresias | B9: Cuota única semestral por miembro | W9: =SUM(C9:V9) -> 0
A10: Stand | B10: Actividad Pro-Fondos | D10: 9 | W10: =SUM(C10:V10) -> 9
A11: Rifas | B11: Eventos | D11: 35 | E11: 5 | W11: =SUM(C11:V11) -> 40
W12: =SUM(C12:V12) -> 0
W13: =SUM(C13:V13) -> 0
W14: =SUM(C14:V14) -> 0
W15: =SUM(C15:V15) -> 0
W16: =SUM(C16:V16) -> 0
W17: =SUM(C17:V17) -> 0
W18: =SUM(C18:V18) -> 0
W19: =SUM(C19:V19) -> 0
W20: =SUM(C20:V20) -> 0
W21: =SUM(C21:V21) -> 0
W22: =SUM(C22:V22) -> 0
W23: =SUM(C23:V23) -> 0
A24: Total Ingresos | C24: =SUM(C9:C23) -> 0 | D24: =SUM(D9:D23) -> 44 | E24: =SUM(E9:E23) -> 5 | F24: =SUM(F9:F23) -> 0 | G24: =SUM(G9:G23) -> 0 | H24: =SUM(H9:H23) -> 0 | I24: =SUM(I9:I23) -> 0 | J24: =SUM(J9:J23) -> 0 | ... W24: =SUM(W9:W23) -> 49
A26: (-) EGRESOS
A27: DEUDA | B27: heredada del 2026-I | C27: 305.5 | W27: =SUM(C27:V27) -> 305.5
A28: Stand | B28: Gastos de logística (dulces) | D28: 22 | W28: =SUM(C28:V28) -> 22
A29: DEUDA UP | B29: Catering UP — 180 Talks 2026-1 | C29: 38.62 | W29: =SUM(C29:V29) -> 38.62
W30: =SUM(C30:V30) -> 0
W31: =SUM(C31:V31) -> 0
W32: =SUM(C32:V32) -> 0
W33: =SUM(C33:V33) -> 0
W34: =SUM(C34:V34) -> 0
W35: =SUM(C35:V35) -> 0
W36: =SUM(C36:V36) -> 0
W37: =SUM(C37:V37) -> 0
W38: =SUM(C38:V38) -> 0
W39: =SUM(C39:V39) -> 0
W40: =SUM(C40:V40) -> 0
W41: =SUM(C41:V41) -> 0
A42: Total Egresos | C42: =SUM(C27:C41) -> 344.12 | D42: =SUM(D27:D41) -> 22 | E42: =SUM(E27:E41) -> 0 | F42: =SUM(F27:F41) -> 0 | G42: =SUM(G27:G41) -> 0 | H42: =SUM(H27:H41) -> 0 | I42: =SUM(I27:I41) -> 0 | J42: =SUM(J27:J41) -> 0 | ... W42: =SUM(W27:W41) -> 366.12
...

Sheet Calendario Actividades
A1: Calendario de Actividades — Semestre 2026-II
A2: Del 17/08/2026 al 28/12/2026
A4: Fecha | B4: Semana | C4: Actividad | D4: Tipo | E4: ¿Genera ingreso/egreso? | F4: Notas
A5: 17/08 | B5: S1 | C5: Ej: Bienvenida del semestre | D5: Integración | E5: Egreso | F5: Editar o borrar — fila de ejemplo
A6: 17/08 | B6: S1
A7: 24/08 | B7: S2
A8: 31/08 | B8: S3
A9: 07/09 | B9: S4
A10: 14/09 | B10: S5
A11: 21/09 | B11: S6
A12: 28/09 | B12: S7
A13: 05/10 | B13: S8
A14: 12/10 | B14: S9
A15: 19/10 | B15: S10
A16: 26/10 | B16: S11
A17: 02/11 | B17: S12
... A25: 28/12 | B25: S20

Sheet Supuestos
A1: Supuestos, Fuentes y Leyenda
A3: ESTRUCTURA DE SEMANAS
A4: Semana | B4: Fechas | C4: Notas
A5: S1 | B5: Lun 17/08 — inicio oficial del semestre
A6: S20 | B6: 28/12 — cierre del semestre
A7: Agosto | B7: S1 a S3 | C7: 3 semana(s) — ver hoja Proyecciones
A8: Septiembre | B8: S4 a S7 | C8: 4 semana(s) — ver hoja Proyecciones
A9: Octubre | B9: S8 a S11 | C9: 4 semana(s) — ver hoja Proyecciones
A10: Noviembre | B10: S12 a S16 | C10: 5 semana(s) — ver hoja Proyecciones
A11: Diciembre | B11: S17 a S20 | C11: 4 semana(s) — ver hoja Proyecciones
A13: SALDO INICIAL
A14: Saldo real al 17/08/2026 | B14: ='Flujo de Caja'!C7 -> 92.87 | C14: Se edita directamente en la celda C7 de la hoja 'Flujo de Caja'.
A16: CÓMO AGREGAR NUEVOS PROYECTOS DE INGRESOS/EGRESOS
A17: 1. Ve a la hoja 'Flujo de Caja'. Cada fila en blanco dentro de INGRESOS o EGRESOS es un proyecto/actividad.
A18: 2. Escribe el nombre del proyecto en la columna 'Concepto' (columna B) y coloca el monto en la semana (S1...S20) donde se recibe o paga.
A19: 3. Si necesitas más filas de las disponibles, haz clic derecho sobre una fila existente dentro del bloque (Ingresos o Egresos) → 'Insertar' → así el Total se recalcula automáticamente.
A20: 4. No edites las filas 'Total Ingresos', 'Total Egresos', 'FLUJO NETO' ni 'SALDO FINAL': son fórmulas.
A21: 5. Actualiza también la hoja 'Calendario Actividades' con la fecha y el tipo de actividad para llevar el registro completo.
A23: LEYENDA DE COLORES
A24: Texto azul + fondo amarillo claro | B24: Celda editable (input) — aquí se escriben montos y nombres de conceptos
A25: Fondo verde claro | B25: Encabezado / sección de Ingresos
A26: Fondo naranja claro | B26: Encabezado / sección de Egresos
A27: Fondo amarillo oscuro | B27: Filas de totales (fórmulas, no editar)
A28: Fondo verde oscuro | B28: Saldo final (fórmula, no editar)
A29: Texto gris cursiva | B29: Fila de ejemplo — se puede editar o borrar

Sheet Proyecciones
A1: Proyecciones Financieras — Semestre 2026-II
A2: Resumen mensual construido a partir de 'Flujo de Caja'. Se actualiza automáticamente.
A4: RESUMEN MENSUAL
A5: Mes | B5: Semanas | C5: Ingresos | D5: Egresos | E5: Flujo Neto | F5: Saldo Final del Mes
A6: Agosto | B6: S1–S3 | C6: =SUM('Flujo de Caja'!C24:E24) -> 49 | D6: =SUM('Flujo de Caja'!C42:E42) -> 366.12 | E6: =C6-D6 -> -317.12 | F6: ='Flujo de Caja'!E45 -> -224.25
A7: Septiembre | B7: S4–S7 | C7: =SUM('Flujo de Caja'!F24:I24) -> 0 | D7: =SUM('Flujo de Caja'!F42:I42) -> 0 | E7: =C7-D7 -> 0 | F7: ='Flujo de Caja'!I45 -> -224.25
A8: Octubre | B8: S8–S11 | C8: =SUM('Flujo de Caja'!J24:M24) -> 0 | D8: =SUM('Flujo de Caja'!J42:M42) -> 0 | E8: =C8-D8 -> 0 | F8: ='Flujo de Caja'!M45 -> -224.25
A9: Noviembre | B9: S12–S16 | C9: =SUM('Flujo de Caja'!N24:R24) -> 0 | D9: =SUM('Flujo de Caja'!N42:R42) -> 0 | E9: =C9-D9 -> 0 | F9: ='Flujo de Caja'!R45 -> -224.25
A10: Diciembre | B10: S17–S20 | C10: =SUM('Flujo de Caja'!S24:V24) -> 0 | D10: =SUM('Flujo de Caja'!S42:V42) -> 0 | E10: =C10-D10 -> 0 | F10: ='Flujo de Caja'!V45 -> -224.25
A11: Total Semestre | C11: =SUM(C6:C10) -> 49 | D11: =SUM(D6:D10) -> 366.12 | E11: =SUM(E6:E10) -> -317.12 | F11: =F10 -> -224.25
A13: ESCENARIOS DE SENSIBILIDAD
A14: Variación de Ingresos (%) | B14: 0.15
A15: Variación de Egresos (%) | B15: 0.1
A17: Escenario | B17: Ingresos | C17: Egresos | D17: Flujo Neto | E17: Saldo Final Proyectado
A18: Pesimista | B18: =$C$11*(1-$B$14) -> 41.65 | C18: =$D$11*(1+$B$15) -> 402.732 | D18: =B18-C18 -> -361.082 | E18: ='Flujo de Caja'!C7+D18 -> -268.212
A19: Base | B19: =$C$11 -> 49 | C19: =$D$11 -> 366.12 | D19: =B19-C19 -> -317.12 | E19: ='Flujo de Caja'!C7+D19 -> -224.25
A20: Optimista | B20: =$C$11*(1+$B$14) -> 56.35 | C20: =$D$11*(1-$B$15) -> 329.508 | D20: =B20-C20 -> -273.158 | E20: ='Flujo de Caja'!C7+D20 -> -180.288
A22: Nota: 'Variación' es un supuesto editable (celdas amarillas) para estresar el resultado base del semestre; no reemplaza el detalle semanal de 'Flujo de Caja'.
